2016-04-05 12:10:41,536 - knowledge_logger - database.py-connect : (1045, "Access denied for user 'root'@'localhost' (using password: YES)")
2016-04-05 12:10:42,346 - knowledge_logger - main.py-handle-api- : 
2016-04-05 12:10:42,346 - knowledge_logger - main.py : Traceback (most recent call last):
  File "/home/solar/projects/Aparajitha-SAAS/Src-server/server/main.py", line 130, in handle_api_request
    self._db.begin()
  File "/home/solar/projects/Aparajitha-SAAS/Src-server/server/database.py", line 128, in begin
    assert self._connection is not None
AssertionError

2016-04-05 12:10:43,430 - knowledge_logger - main.py-handle-api- : 
2016-04-05 12:10:43,431 - knowledge_logger - main.py : Traceback (most recent call last):
  File "/home/solar/projects/Aparajitha-SAAS/Src-server/server/main.py", line 130, in handle_api_request
    self._db.begin()
  File "/home/solar/projects/Aparajitha-SAAS/Src-server/server/database.py", line 128, in begin
    assert self._connection is not None
AssertionError

2016-04-05 12:11:42,736 - knowledge_logger - database.py-connect : (1045, "Access denied for user 'root'@'localhost' (using password: YES)")
2016-04-05 12:11:43,445 - knowledge_logger - main.py-handle-api- : 
2016-04-05 12:11:43,445 - knowledge_logger - main.py : Traceback (most recent call last):
  File "/home/solar/projects/Aparajitha-SAAS/Src-server/server/main.py", line 130, in handle_api_request
    self._db.begin()
  File "/home/solar/projects/Aparajitha-SAAS/Src-server/server/database.py", line 128, in begin
    assert self._connection is not None
AssertionError

2016-04-05 12:11:57,605 - knowledge_logger - database.py-connect : (1045, "Access denied for user 'root'@'localhost' (using password: YES)")
2016-04-05 12:12:42,390 - knowledge_logger - main.py-handle-api- : 
2016-04-05 12:12:42,391 - knowledge_logger - main.py : Traceback (most recent call last):
  File "/home/solar/projects/Aparajitha-SAAS/Src-server/server/main.py", line 130, in handle_api_request
    self._db.begin()
  File "/home/solar/projects/Aparajitha-SAAS/Src-server/server/database.py", line 128, in begin
    assert self._connection is not None
AssertionError

2016-04-05 12:12:43,509 - knowledge_logger - main.py-handle-api- : 
2016-04-05 12:12:43,509 - knowledge_logger - main.py : Traceback (most recent call last):
  File "/home/solar/projects/Aparajitha-SAAS/Src-server/server/main.py", line 130, in handle_api_request
    self._db.begin()
  File "/home/solar/projects/Aparajitha-SAAS/Src-server/server/database.py", line 128, in begin
    assert self._connection is not None
AssertionError

