2016-09-21 11:15:59,976 - knowledge_logger - main.py-handle-api- : list index out of range 

2016-09-21 11:15:59,980 - knowledge_logger - main.py : Traceback (most recent call last):
  File "C:\Users\Minds\PycharmProjects\compliance_mirror\Src-server\server\main.py", line 162, in handle_api_request
    response_data = unbound_method(self, request_data, self._db)
  File "C:\Users\Minds\PycharmProjects\compliance_mirror\Src-server\server\main.py", line 261, in handle_techno
    return controller.process_techno_request(request, db)
  File "C:\Users\Minds\PycharmProjects\compliance_mirror\Src-server\server\controller\technocontroller.py", line 70, in process_techno_request
    result = get_clients(db, request_frame, session_user)
  File "C:\Users\Minds\PycharmProjects\compliance_mirror\Src-server\server\controller\technomastercontroller.py", line 407, in get_clients
    db, session_user
  File "C:\Users\Minds\PycharmProjects\compliance_mirror\Src-server\server\database\technomaster.py", line 1225, in get_group_companies_for_user_with_max_unit_count
    "client_id", client_ids
  File "C:\Users\Minds\PycharmProjects\compliance_mirror\Src-server\server\dbase.py", line 348, in generate_tuple_condition
    condition_val = values_list[0]
IndexError: list index out of range
 

2016-09-21 11:31:04,214 - knowledge_logger - main.py-handle-api- : list index out of range 

2016-09-21 11:31:04,219 - knowledge_logger - main.py : Traceback (most recent call last):
  File "C:\Users\Minds\PycharmProjects\compliance_mirror\Src-server\server\main.py", line 162, in handle_api_request
    response_data = unbound_method(self, request_data, self._db)
  File "C:\Users\Minds\PycharmProjects\compliance_mirror\Src-server\server\main.py", line 261, in handle_techno
    return controller.process_techno_request(request, db)
  File "C:\Users\Minds\PycharmProjects\compliance_mirror\Src-server\server\controller\technocontroller.py", line 70, in process_techno_request
    result = get_clients(db, request_frame, session_user)
  File "C:\Users\Minds\PycharmProjects\compliance_mirror\Src-server\server\controller\technomastercontroller.py", line 407, in get_clients
    db, session_user
  File "C:\Users\Minds\PycharmProjects\compliance_mirror\Src-server\server\database\technomaster.py", line 1225, in get_group_companies_for_user_with_max_unit_count
    "client_id", client_ids
  File "C:\Users\Minds\PycharmProjects\compliance_mirror\Src-server\server\dbase.py", line 348, in generate_tuple_condition
    condition_val = values_list[0]
IndexError: list index out of range
 

2016-09-21 11:46:27,155 - knowledge_logger - main.py-handle-api- : list index out of range 

2016-09-21 11:46:27,157 - knowledge_logger - main.py : Traceback (most recent call last):
  File "C:\Users\Minds\PycharmProjects\compliance_mirror\Src-server\server\main.py", line 162, in handle_api_request
    response_data = unbound_method(self, request_data, self._db)
  File "C:\Users\Minds\PycharmProjects\compliance_mirror\Src-server\server\main.py", line 261, in handle_techno
    return controller.process_techno_request(request, db)
  File "C:\Users\Minds\PycharmProjects\compliance_mirror\Src-server\server\controller\technocontroller.py", line 70, in process_techno_request
    result = get_clients(db, request_frame, session_user)
  File "C:\Users\Minds\PycharmProjects\compliance_mirror\Src-server\server\controller\technomastercontroller.py", line 407, in get_clients
    db, session_user
  File "C:\Users\Minds\PycharmProjects\compliance_mirror\Src-server\server\database\technomaster.py", line 1225, in get_group_companies_for_user_with_max_unit_count
    "client_id", client_ids
  File "C:\Users\Minds\PycharmProjects\compliance_mirror\Src-server\server\dbase.py", line 348, in generate_tuple_condition
    condition_val = values_list[0]
IndexError: list index out of range
 

2016-09-21 11:48:42,134 - knowledge_logger - main.py-handle-api- :  

2016-09-21 11:48:42,134 - knowledge_logger - main.py : Traceback (most recent call last):
  File "C:\Users\Minds\PycharmProjects\compliance_mirror\Src-server\server\main.py", line 161, in handle_api_request
    self._db.begin()
  File "C:\Users\Minds\PycharmProjects\compliance_mirror\Src-server\server\dbase.py", line 109, in begin
    assert self._cursor is None
AssertionError
 

2016-09-21 11:48:44,371 - knowledge_logger - main.py-handle-api- :  

2016-09-21 11:48:44,371 - knowledge_logger - main.py : Traceback (most recent call last):
  File "C:\Users\Minds\PycharmProjects\compliance_mirror\Src-server\server\main.py", line 161, in handle_api_request
    self._db.begin()
  File "C:\Users\Minds\PycharmProjects\compliance_mirror\Src-server\server\dbase.py", line 109, in begin
    assert self._cursor is None
AssertionError
 

2016-09-21 11:49:16,772 - knowledge_logger - main.py-handle-api- :  

2016-09-21 11:49:16,773 - knowledge_logger - main.py : Traceback (most recent call last):
  File "C:\Users\Minds\PycharmProjects\compliance_mirror\Src-server\server\main.py", line 161, in handle_api_request
    self._db.begin()
  File "C:\Users\Minds\PycharmProjects\compliance_mirror\Src-server\server\dbase.py", line 109, in begin
    assert self._cursor is None
AssertionError
 

2016-09-21 12:04:57,127 - knowledge_logger - main.py-handle-api- : sp_client_groups_list- None- (1305, 'PROCEDURE compfie_knowledge.sp_client_groups_list does not exist') 

2016-09-21 12:04:57,128 - knowledge_logger - main.py : Traceback (most recent call last):
  File "C:\Users\Minds\PycharmProjects\compliance_mirror\Src-server\server\main.py", line 162, in handle_api_request
    response_data = unbound_method(self, request_data, self._db)
  File "C:\Users\Minds\PycharmProjects\compliance_mirror\Src-server\server\main.py", line 261, in handle_techno
    return controller.process_techno_request(request, db)
  File "C:\Users\Minds\PycharmProjects\compliance_mirror\Src-server\server\controller\technocontroller.py", line 42, in process_techno_request
    result = get_client_groups(db, request_frame, session_user)
  File "C:\Users\Minds\PycharmProjects\compliance_mirror\Src-server\server\controller\technomastercontroller.py", line 51, in get_client_groups
    groups = get_groups(db)
  File "C:\Users\Minds\PycharmProjects\compliance_mirror\Src-server\server\database\technomaster.py", line 266, in get_groups
    "sp_client_groups_list", None, columns
  File "C:\Users\Minds\PycharmProjects\compliance_mirror\Src-server\server\dbase.py", line 663, in call_proc
    raise process_procedure_error(procedure_name, args, e)
RuntimeError: sp_client_groups_list- None- (1305, 'PROCEDURE compfie_knowledge.sp_client_groups_list does not exist')
 

2016-09-21 12:05:01,019 - knowledge_logger - main.py-handle-api- :  

2016-09-21 12:05:01,019 - knowledge_logger - main.py : Traceback (most recent call last):
  File "C:\Users\Minds\PycharmProjects\compliance_mirror\Src-server\server\main.py", line 161, in handle_api_request
    self._db.begin()
  File "C:\Users\Minds\PycharmProjects\compliance_mirror\Src-server\server\dbase.py", line 109, in begin
    assert self._cursor is None
AssertionError
 

2016-09-21 12:29:31,417 - knowledge_logger - main.py-handle-api- :  

2016-09-21 12:29:31,418 - knowledge_logger - main.py : Traceback (most recent call last):
  File "C:\Users\Minds\PycharmProjects\compliance_mirror\Src-server\server\main.py", line 161, in handle_api_request
    self._db.begin()
  File "C:\Users\Minds\PycharmProjects\compliance_mirror\Src-server\server\dbase.py", line 109, in begin
    assert self._cursor is None
AssertionError
 

2016-09-21 12:29:34,815 - knowledge_logger - main.py-handle-api- :  

2016-09-21 12:29:34,825 - knowledge_logger - main.py : Traceback (most recent call last):
  File "C:\Users\Minds\PycharmProjects\compliance_mirror\Src-server\server\main.py", line 161, in handle_api_request
    self._db.begin()
  File "C:\Users\Minds\PycharmProjects\compliance_mirror\Src-server\server\dbase.py", line 109, in begin
    assert self._cursor is None
AssertionError
 

