2016-10-22 10:04:28,509 - knowledge_logger - main.py-parse-request : null is not allowed 

2016-10-22 10:04:28,535 - knowledge_logger - main.py : Traceback (most recent call last):
  File "/home/thickpadi5/Projects/aparajitha-saas/Src-server/server/main.py", line 124, in _parse_request
    data
  File "/home/thickpadi5/Projects/aparajitha-saas/Src-server/protocol/technomasters.py", line 1922, in parse_structure
    data = parse_dictionary(data, ["session_token", "request"])
  File "/home/thickpadi5/Projects/aparajitha-saas/Src-server/protocol/jsonvalidators.py", line 189, in parse_dictionary
    x = parse_dictionary_values(x, field_names, True)
  File "/home/thickpadi5/Projects/aparajitha-saas/Src-server/protocol/jsonvalidators.py", line 372, in parse_dictionary_values
    val = parse_values(field_name, param, val)
  File "/home/thickpadi5/Projects/aparajitha-saas/Src-server/protocol/jsonvalidators.py", line 273, in parse_values
    val = parse_string(val)
  File "/home/thickpadi5/Projects/aparajitha-saas/Src-server/protocol/jsonvalidators.py", line 79, in parse_string
    raise empty_error()
ValueError: null is not allowed
 

2016-10-22 10:05:46,703 - knowledge_logger - main.py-parse-request : user_type is not configured in settings 

2016-10-22 10:05:46,703 - knowledge_logger - main.py : Traceback (most recent call last):
  File "/home/thickpadi5/Projects/aparajitha-saas/Src-server/server/main.py", line 124, in _parse_request
    data
  File "/home/thickpadi5/Projects/aparajitha-saas/Src-server/protocol/admin.py", line 1025, in parse_structure
    request, "admin", "Request"
  File "/home/thickpadi5/Projects/aparajitha-saas/Src-server/protocol/jsonvalidators.py", line 467, in parse_VariantType
    return klass.parse_structure(data)
  File "/home/thickpadi5/Projects/aparajitha-saas/Src-server/protocol/admin.py", line 34, in parse_structure
    return _Request_class_map[name].parse_inner_structure(data)
  File "/home/thickpadi5/Projects/aparajitha-saas/Src-server/protocol/admin.py", line 367, in parse_inner_structure
    "user_type", "old_user_id", "new_user_id", "assigned_ids"
  File "/home/thickpadi5/Projects/aparajitha-saas/Src-server/protocol/jsonvalidators.py", line 189, in parse_dictionary
    x = parse_dictionary_values(x, field_names, True)
  File "/home/thickpadi5/Projects/aparajitha-saas/Src-server/protocol/jsonvalidators.py", line 318, in parse_dictionary_values
    raise ValueError('%s is not configured in settings' % (field_name))
ValueError: user_type is not configured in settings
 

2016-10-22 10:08:34,404 - knowledge_logger - main.py-parse-request : expected a list with integer values , but received: [u'1'] 

2016-10-22 10:08:34,404 - knowledge_logger - main.py : Traceback (most recent call last):
  File "/home/thickpadi5/Projects/aparajitha-saas/Src-server/server/main.py", line 124, in _parse_request
    data
  File "/home/thickpadi5/Projects/aparajitha-saas/Src-server/protocol/admin.py", line 1025, in parse_structure
    request, "admin", "Request"
  File "/home/thickpadi5/Projects/aparajitha-saas/Src-server/protocol/jsonvalidators.py", line 467, in parse_VariantType
    return klass.parse_structure(data)
  File "/home/thickpadi5/Projects/aparajitha-saas/Src-server/protocol/admin.py", line 34, in parse_structure
    return _Request_class_map[name].parse_inner_structure(data)
  File "/home/thickpadi5/Projects/aparajitha-saas/Src-server/protocol/admin.py", line 367, in parse_inner_structure
    "user_type", "old_user_id", "new_user_id", "assigned_ids"
  File "/home/thickpadi5/Projects/aparajitha-saas/Src-server/protocol/jsonvalidators.py", line 189, in parse_dictionary
    x = parse_dictionary_values(x, field_names, True)
  File "/home/thickpadi5/Projects/aparajitha-saas/Src-server/protocol/jsonvalidators.py", line 372, in parse_dictionary_values
    val = parse_values(field_name, param, val)
  File "/home/thickpadi5/Projects/aparajitha-saas/Src-server/protocol/jsonvalidators.py", line 305, in parse_values
    val = parse_int_list(val, int_length=_length)
  File "/home/thickpadi5/Projects/aparajitha-saas/Src-server/protocol/jsonvalidators.py", line 242, in parse_int_list
    raise expectation_error("a list with integer values ", x)
ValueError: expected a list with integer values , but received: [u'1']
 

2016-10-22 10:09:10,577 - knowledge_logger - main.py-parse-request : null is not allowed 

2016-10-22 10:09:10,577 - knowledge_logger - main.py : Traceback (most recent call last):
  File "/home/thickpadi5/Projects/aparajitha-saas/Src-server/server/main.py", line 124, in _parse_request
    data
  File "/home/thickpadi5/Projects/aparajitha-saas/Src-server/protocol/technomasters.py", line 1922, in parse_structure
    data = parse_dictionary(data, ["session_token", "request"])
  File "/home/thickpadi5/Projects/aparajitha-saas/Src-server/protocol/jsonvalidators.py", line 189, in parse_dictionary
    x = parse_dictionary_values(x, field_names, True)
  File "/home/thickpadi5/Projects/aparajitha-saas/Src-server/protocol/jsonvalidators.py", line 372, in parse_dictionary_values
    val = parse_values(field_name, param, val)
  File "/home/thickpadi5/Projects/aparajitha-saas/Src-server/protocol/jsonvalidators.py", line 273, in parse_values
    val = parse_string(val)
  File "/home/thickpadi5/Projects/aparajitha-saas/Src-server/protocol/jsonvalidators.py", line 79, in parse_string
    raise empty_error()
ValueError: null is not allowed
 

2016-10-22 10:09:43,336 - knowledge_logger - main.py-parse-request : expected a list with integer values , but received: [u'1'] 

2016-10-22 10:09:43,336 - knowledge_logger - main.py : Traceback (most recent call last):
  File "/home/thickpadi5/Projects/aparajitha-saas/Src-server/server/main.py", line 124, in _parse_request
    data
  File "/home/thickpadi5/Projects/aparajitha-saas/Src-server/protocol/admin.py", line 1025, in parse_structure
    request, "admin", "Request"
  File "/home/thickpadi5/Projects/aparajitha-saas/Src-server/protocol/jsonvalidators.py", line 467, in parse_VariantType
    return klass.parse_structure(data)
  File "/home/thickpadi5/Projects/aparajitha-saas/Src-server/protocol/admin.py", line 34, in parse_structure
    return _Request_class_map[name].parse_inner_structure(data)
  File "/home/thickpadi5/Projects/aparajitha-saas/Src-server/protocol/admin.py", line 367, in parse_inner_structure
    "user_type", "old_user_id", "new_user_id", "assigned_ids"
  File "/home/thickpadi5/Projects/aparajitha-saas/Src-server/protocol/jsonvalidators.py", line 189, in parse_dictionary
    x = parse_dictionary_values(x, field_names, True)
  File "/home/thickpadi5/Projects/aparajitha-saas/Src-server/protocol/jsonvalidators.py", line 372, in parse_dictionary_values
    val = parse_values(field_name, param, val)
  File "/home/thickpadi5/Projects/aparajitha-saas/Src-server/protocol/jsonvalidators.py", line 305, in parse_values
    val = parse_int_list(val, int_length=_length)
  File "/home/thickpadi5/Projects/aparajitha-saas/Src-server/protocol/jsonvalidators.py", line 242, in parse_int_list
    raise expectation_error("a list with integer values ", x)
ValueError: expected a list with integer values , but received: [u'1']
 

2016-10-22 10:10:35,856 - knowledge_logger - main.py-parse-request : null is not allowed 

2016-10-22 10:10:35,856 - knowledge_logger - main.py : Traceback (most recent call last):
  File "/home/thickpadi5/Projects/aparajitha-saas/Src-server/server/main.py", line 124, in _parse_request
    data
  File "/home/thickpadi5/Projects/aparajitha-saas/Src-server/protocol/technomasters.py", line 1922, in parse_structure
    data = parse_dictionary(data, ["session_token", "request"])
  File "/home/thickpadi5/Projects/aparajitha-saas/Src-server/protocol/jsonvalidators.py", line 189, in parse_dictionary
    x = parse_dictionary_values(x, field_names, True)
  File "/home/thickpadi5/Projects/aparajitha-saas/Src-server/protocol/jsonvalidators.py", line 372, in parse_dictionary_values
    val = parse_values(field_name, param, val)
  File "/home/thickpadi5/Projects/aparajitha-saas/Src-server/protocol/jsonvalidators.py", line 273, in parse_values
    val = parse_string(val)
  File "/home/thickpadi5/Projects/aparajitha-saas/Src-server/protocol/jsonvalidators.py", line 79, in parse_string
    raise empty_error()
ValueError: null is not allowed
 

2016-10-22 10:11:04,971 - knowledge_logger - main.py-handle-api- : global name 'save_reassigned_user_account' is not defined 

2016-10-22 10:11:04,971 - knowledge_logger - main.py : Traceback (most recent call last):
  File "/home/thickpadi5/Projects/aparajitha-saas/Src-server/server/main.py", line 164, in handle_api_request
    response_data = unbound_method(self, request_data, self._db)
  File "/home/thickpadi5/Projects/aparajitha-saas/Src-server/server/main.py", line 260, in handle_admin
    return controller.process_admin_request(request, db)
  File "/home/thickpadi5/Projects/aparajitha-saas/Src-server/server/controller/admincontroller.py", line 113, in process_admin_request
    db, request_frame, session_user)
  File "/home/thickpadi5/Projects/aparajitha-saas/Src-server/server/controller/admincontroller.py", line 509, in process_save_reassign_user_account_request
    save_reassigned_user_account(db, request, session_user)
NameError: global name 'save_reassigned_user_account' is not defined
 

2016-10-22 10:11:35,952 - knowledge_logger - main.py-handle-api- : append() takes exactly one argument (3 given) 

2016-10-22 10:11:35,953 - knowledge_logger - main.py : Traceback (most recent call last):
  File "/home/thickpadi5/Projects/aparajitha-saas/Src-server/server/main.py", line 164, in handle_api_request
    response_data = unbound_method(self, request_data, self._db)
  File "/home/thickpadi5/Projects/aparajitha-saas/Src-server/server/main.py", line 260, in handle_admin
    return controller.process_admin_request(request, db)
  File "/home/thickpadi5/Projects/aparajitha-saas/Src-server/server/controller/admincontroller.py", line 113, in process_admin_request
    db, request_frame, session_user)
  File "/home/thickpadi5/Projects/aparajitha-saas/Src-server/server/controller/admincontroller.py", line 509, in process_save_reassign_user_account_request
    save_reassigned_user_account(db, request, session_user)
  File "/home/thickpadi5/Projects/aparajitha-saas/Src-server/server/database/admin.py", line 977, in save_reassigned_user_account
    request.new_user_id, session_user, current_time_stamp
TypeError: append() takes exactly one argument (3 given)
 

2016-10-22 10:26:20,962 - knowledge_logger - main.py-parse-request : null is not allowed 

2016-10-22 10:26:20,962 - knowledge_logger - main.py : Traceback (most recent call last):
  File "/home/thickpadi5/Projects/aparajitha-saas/Src-server/server/main.py", line 124, in _parse_request
    data
  File "/home/thickpadi5/Projects/aparajitha-saas/Src-server/protocol/technomasters.py", line 1922, in parse_structure
    data = parse_dictionary(data, ["session_token", "request"])
  File "/home/thickpadi5/Projects/aparajitha-saas/Src-server/protocol/jsonvalidators.py", line 189, in parse_dictionary
    x = parse_dictionary_values(x, field_names, True)
  File "/home/thickpadi5/Projects/aparajitha-saas/Src-server/protocol/jsonvalidators.py", line 369, in parse_dictionary_values
    val = parse_values(field_name, param, val)
  File "/home/thickpadi5/Projects/aparajitha-saas/Src-server/protocol/jsonvalidators.py", line 272, in parse_values
    val = parse_string(val)
  File "/home/thickpadi5/Projects/aparajitha-saas/Src-server/protocol/jsonvalidators.py", line 79, in parse_string
    raise empty_error()
ValueError: null is not allowed
 

2016-10-22 10:27:13,965 - knowledge_logger - main.py-parse-request : null is not allowed 

2016-10-22 10:27:13,965 - knowledge_logger - main.py : Traceback (most recent call last):
  File "/home/thickpadi5/Projects/aparajitha-saas/Src-server/server/main.py", line 124, in _parse_request
    data
  File "/home/thickpadi5/Projects/aparajitha-saas/Src-server/protocol/technomasters.py", line 1922, in parse_structure
    data = parse_dictionary(data, ["session_token", "request"])
  File "/home/thickpadi5/Projects/aparajitha-saas/Src-server/protocol/jsonvalidators.py", line 189, in parse_dictionary
    x = parse_dictionary_values(x, field_names, True)
  File "/home/thickpadi5/Projects/aparajitha-saas/Src-server/protocol/jsonvalidators.py", line 369, in parse_dictionary_values
    val = parse_values(field_name, param, val)
  File "/home/thickpadi5/Projects/aparajitha-saas/Src-server/protocol/jsonvalidators.py", line 272, in parse_values
    val = parse_string(val)
  File "/home/thickpadi5/Projects/aparajitha-saas/Src-server/protocol/jsonvalidators.py", line 79, in parse_string
    raise empty_error()
ValueError: null is not allowed
 

2016-10-22 10:27:43,895 - knowledge_logger - main.py-handle-api- : tuple index out of range 

2016-10-22 10:27:43,895 - knowledge_logger - main.py : Traceback (most recent call last):
  File "/home/thickpadi5/Projects/aparajitha-saas/Src-server/server/main.py", line 164, in handle_api_request
    response_data = unbound_method(self, request_data, self._db)
  File "/home/thickpadi5/Projects/aparajitha-saas/Src-server/server/main.py", line 260, in handle_admin
    return controller.process_admin_request(request, db)
  File "/home/thickpadi5/Projects/aparajitha-saas/Src-server/server/controller/admincontroller.py", line 113, in process_admin_request
    db, request_frame, session_user)
  File "/home/thickpadi5/Projects/aparajitha-saas/Src-server/server/controller/admincontroller.py", line 509, in process_save_reassign_user_account_request
    save_reassigned_user_account(db, request, session_user)
  File "/home/thickpadi5/Projects/aparajitha-saas/Src-server/server/database/admin.py", line 994, in save_reassigned_user_account
    table, columns, value_list, conditions
  File "/home/thickpadi5/Projects/aparajitha-saas/Src-server/server/dbase.py", line 477, in bulk_update
    if values[outer_index][index] is not None:
IndexError: tuple index out of range
 

2016-10-22 10:37:15,602 - knowledge_logger - main.py-parse-request : null is not allowed 

2016-10-22 10:37:15,603 - knowledge_logger - main.py : Traceback (most recent call last):
  File "/home/thickpadi5/Projects/aparajitha-saas/Src-server/server/main.py", line 124, in _parse_request
    data
  File "/home/thickpadi5/Projects/aparajitha-saas/Src-server/protocol/technomasters.py", line 1922, in parse_structure
    data = parse_dictionary(data, ["session_token", "request"])
  File "/home/thickpadi5/Projects/aparajitha-saas/Src-server/protocol/jsonvalidators.py", line 189, in parse_dictionary
    x = parse_dictionary_values(x, field_names, True)
  File "/home/thickpadi5/Projects/aparajitha-saas/Src-server/protocol/jsonvalidators.py", line 369, in parse_dictionary_values
    val = parse_values(field_name, param, val)
  File "/home/thickpadi5/Projects/aparajitha-saas/Src-server/protocol/jsonvalidators.py", line 272, in parse_values
    val = parse_string(val)
  File "/home/thickpadi5/Projects/aparajitha-saas/Src-server/protocol/jsonvalidators.py", line 79, in parse_string
    raise empty_error()
ValueError: null is not allowed
 

2016-10-22 10:45:26,245 - knowledge_logger - main.py-parse-request : null is not allowed 

2016-10-22 10:45:26,245 - knowledge_logger - main.py : Traceback (most recent call last):
  File "/home/thickpadi5/Projects/aparajitha-saas/Src-server/server/main.py", line 124, in _parse_request
    data
  File "/home/thickpadi5/Projects/aparajitha-saas/Src-server/protocol/technomasters.py", line 1922, in parse_structure
    data = parse_dictionary(data, ["session_token", "request"])
  File "/home/thickpadi5/Projects/aparajitha-saas/Src-server/protocol/jsonvalidators.py", line 189, in parse_dictionary
    x = parse_dictionary_values(x, field_names, True)
  File "/home/thickpadi5/Projects/aparajitha-saas/Src-server/protocol/jsonvalidators.py", line 369, in parse_dictionary_values
    val = parse_values(field_name, param, val)
  File "/home/thickpadi5/Projects/aparajitha-saas/Src-server/protocol/jsonvalidators.py", line 272, in parse_values
    val = parse_string(val)
  File "/home/thickpadi5/Projects/aparajitha-saas/Src-server/protocol/jsonvalidators.py", line 79, in parse_string
    raise empty_error()
ValueError: null is not allowed
 

2016-10-21 12:30:53,994 - knowledge_logger - main.py-handle-api- : execute() first 

2016-10-21 12:30:53,994 - knowledge_logger - main.py : Traceback (most recent call last):
  File "/home/minds/projects/Aparajitha-SAAS/Src-server/server/main.py", line 162, in handle_api_request
    response_data = unbound_method(self, request_data, self._db)
  File "/home/minds/projects/Aparajitha-SAAS/Src-server/server/main.py", line 253, in handle_login
    return controller.process_login_request(request, db, self._ip_addess)
  File "/home/minds/projects/Aparajitha-SAAS/Src-server/server/controller/logincontroller.py", line 29, in process_login_request
    result = process_login(db, request, session_user_ip)
  File "/home/minds/projects/Aparajitha-SAAS/Src-server/server/controller/logincontroller.py", line 65, in process_login
    response = verify_login(db, username, encrypt_password)
  File "/home/minds/projects/Aparajitha-SAAS/Src-server/server/database/login.py", line 29, in verify_login
    "sp_verify_login", args, expected_result
  File "/home/minds/projects/Aparajitha-SAAS/Src-server/server/dbase.py", line 753, in call_proc_with_multiresult_set
    r = convert_to_dict(cursor.fetchall(), cols)
  File "/usr/lib/python2.7/dist-packages/MySQLdb/cursors.py", line 406, in fetchall
    self._check_executed()
  File "/usr/lib/python2.7/dist-packages/MySQLdb/cursors.py", line 107, in _check_executed
    self.errorhandler(self, ProgrammingError, "execute() first")
  File "/usr/lib/python2.7/dist-packages/MySQLdb/connections.py", line 38, in defaulterrorhandler
    raise errorclass(errorvalue)
ProgrammingError: execute() first
 

2016-10-21 12:35:45,198 - knowledge_logger - main.py-handle-api- : execute() first 

2016-10-21 12:35:45,199 - knowledge_logger - main.py : Traceback (most recent call last):
  File "/home/minds/projects/Aparajitha-SAAS/Src-server/server/main.py", line 162, in handle_api_request
    response_data = unbound_method(self, request_data, self._db)
  File "/home/minds/projects/Aparajitha-SAAS/Src-server/server/main.py", line 253, in handle_login
    return controller.process_login_request(request, db, self._ip_addess)
  File "/home/minds/projects/Aparajitha-SAAS/Src-server/server/controller/logincontroller.py", line 29, in process_login_request
    result = process_login(db, request, session_user_ip)
  File "/home/minds/projects/Aparajitha-SAAS/Src-server/server/controller/logincontroller.py", line 65, in process_login
    response = verify_login(db, username, encrypt_password)
  File "/home/minds/projects/Aparajitha-SAAS/Src-server/server/database/login.py", line 29, in verify_login
    "sp_verify_login", args, expected_result
  File "/home/minds/projects/Aparajitha-SAAS/Src-server/server/dbase.py", line 753, in call_proc_with_multiresult_set
    r = convert_to_dict(cursor.fetchall(), cols)
  File "/usr/lib/python2.7/dist-packages/MySQLdb/cursors.py", line 406, in fetchall
    self._check_executed()
  File "/usr/lib/python2.7/dist-packages/MySQLdb/cursors.py", line 107, in _check_executed
    self.errorhandler(self, ProgrammingError, "execute() first")
  File "/usr/lib/python2.7/dist-packages/MySQLdb/connections.py", line 38, in defaulterrorhandler
    raise errorclass(errorvalue)
ProgrammingError: execute() first
 

2016-10-21 12:37:04,398 - knowledge_logger - main.py-handle-api- : execute() first 

2016-10-21 12:37:04,398 - knowledge_logger - main.py : Traceback (most recent call last):
  File "/home/minds/projects/Aparajitha-SAAS/Src-server/server/main.py", line 162, in handle_api_request
    response_data = unbound_method(self, request_data, self._db)
  File "/home/minds/projects/Aparajitha-SAAS/Src-server/server/main.py", line 253, in handle_login
    return controller.process_login_request(request, db, self._ip_addess)
  File "/home/minds/projects/Aparajitha-SAAS/Src-server/server/controller/logincontroller.py", line 29, in process_login_request
    result = process_login(db, request, session_user_ip)
  File "/home/minds/projects/Aparajitha-SAAS/Src-server/server/controller/logincontroller.py", line 65, in process_login
    response = verify_login(db, username, encrypt_password)
  File "/home/minds/projects/Aparajitha-SAAS/Src-server/server/database/login.py", line 29, in verify_login
    "sp_verify_login", args, expected_result
  File "/home/minds/projects/Aparajitha-SAAS/Src-server/server/dbase.py", line 753, in call_proc_with_multiresult_set
    r = convert_to_dict(cursor.fetchall(), cols)
  File "/usr/lib/python2.7/dist-packages/MySQLdb/cursors.py", line 406, in fetchall
    self._check_executed()
  File "/usr/lib/python2.7/dist-packages/MySQLdb/cursors.py", line 107, in _check_executed
    self.errorhandler(self, ProgrammingError, "execute() first")
  File "/usr/lib/python2.7/dist-packages/MySQLdb/connections.py", line 38, in defaulterrorhandler
    raise errorclass(errorvalue)
ProgrammingError: execute() first
 

2016-10-21 12:37:14,454 - knowledge_logger - main.py-handle-api- : execute() first 

2016-10-21 12:37:14,454 - knowledge_logger - main.py : Traceback (most recent call last):
  File "/home/minds/projects/Aparajitha-SAAS/Src-server/server/main.py", line 162, in handle_api_request
    response_data = unbound_method(self, request_data, self._db)
  File "/home/minds/projects/Aparajitha-SAAS/Src-server/server/main.py", line 253, in handle_login
    return controller.process_login_request(request, db, self._ip_addess)
  File "/home/minds/projects/Aparajitha-SAAS/Src-server/server/controller/logincontroller.py", line 29, in process_login_request
    result = process_login(db, request, session_user_ip)
  File "/home/minds/projects/Aparajitha-SAAS/Src-server/server/controller/logincontroller.py", line 65, in process_login
    response = verify_login(db, username, encrypt_password)
  File "/home/minds/projects/Aparajitha-SAAS/Src-server/server/database/login.py", line 29, in verify_login
    "sp_verify_login", args, expected_result
  File "/home/minds/projects/Aparajitha-SAAS/Src-server/server/dbase.py", line 753, in call_proc_with_multiresult_set
    r = convert_to_dict(cursor.fetchall(), cols)
  File "/usr/lib/python2.7/dist-packages/MySQLdb/cursors.py", line 406, in fetchall
    self._check_executed()
  File "/usr/lib/python2.7/dist-packages/MySQLdb/cursors.py", line 107, in _check_executed
    self.errorhandler(self, ProgrammingError, "execute() first")
  File "/usr/lib/python2.7/dist-packages/MySQLdb/connections.py", line 38, in defaulterrorhandler
    raise errorclass(errorvalue)
ProgrammingError: execute() first
 

2016-10-21 12:38:35,147 - knowledge_logger - main.py-handle-api- : execute() first 

2016-10-21 12:38:35,148 - knowledge_logger - main.py : Traceback (most recent call last):
  File "/home/minds/projects/Aparajitha-SAAS/Src-server/server/main.py", line 162, in handle_api_request
    response_data = unbound_method(self, request_data, self._db)
  File "/home/minds/projects/Aparajitha-SAAS/Src-server/server/main.py", line 253, in handle_login
    return controller.process_login_request(request, db, self._ip_addess)
  File "/home/minds/projects/Aparajitha-SAAS/Src-server/server/controller/logincontroller.py", line 29, in process_login_request
    result = process_login(db, request, session_user_ip)
  File "/home/minds/projects/Aparajitha-SAAS/Src-server/server/controller/logincontroller.py", line 65, in process_login
    response = verify_login(db, username, encrypt_password)
  File "/home/minds/projects/Aparajitha-SAAS/Src-server/server/database/login.py", line 29, in verify_login
    "sp_verify_login", args, expected_result
  File "/home/minds/projects/Aparajitha-SAAS/Src-server/server/dbase.py", line 753, in call_proc_with_multiresult_set
    r = convert_to_dict(cursor.fetchall(), cols)
  File "/usr/lib/python2.7/dist-packages/MySQLdb/cursors.py", line 406, in fetchall
    self._check_executed()
  File "/usr/lib/python2.7/dist-packages/MySQLdb/cursors.py", line 107, in _check_executed
    self.errorhandler(self, ProgrammingError, "execute() first")
  File "/usr/lib/python2.7/dist-packages/MySQLdb/connections.py", line 38, in defaulterrorhandler
    raise errorclass(errorvalue)
ProgrammingError: execute() first
 

2016-10-21 12:48:42,665 - knowledge_logger - main.py-handle-api- : execute() first 

2016-10-21 12:48:42,666 - knowledge_logger - main.py : Traceback (most recent call last):
  File "/home/minds/projects/Aparajitha-SAAS/Src-server/server/main.py", line 162, in handle_api_request
    response_data = unbound_method(self, request_data, self._db)
  File "/home/minds/projects/Aparajitha-SAAS/Src-server/server/main.py", line 253, in handle_login
    return controller.process_login_request(request, db, self._ip_addess)
  File "/home/minds/projects/Aparajitha-SAAS/Src-server/server/controller/logincontroller.py", line 29, in process_login_request
    result = process_login(db, request, session_user_ip)
  File "/home/minds/projects/Aparajitha-SAAS/Src-server/server/controller/logincontroller.py", line 65, in process_login
    response = verify_login(db, username, encrypt_password)
  File "/home/minds/projects/Aparajitha-SAAS/Src-server/server/database/login.py", line 29, in verify_login
    "sp_verify_login", args, expected_result
  File "/home/minds/projects/Aparajitha-SAAS/Src-server/server/dbase.py", line 753, in call_proc_with_multiresult_set
    r = convert_to_dict(cursor.fetchall(), cols)
  File "/usr/lib/python2.7/dist-packages/MySQLdb/cursors.py", line 406, in fetchall
    self._check_executed()
  File "/usr/lib/python2.7/dist-packages/MySQLdb/cursors.py", line 107, in _check_executed
    self.errorhandler(self, ProgrammingError, "execute() first")
  File "/usr/lib/python2.7/dist-packages/MySQLdb/connections.py", line 38, in defaulterrorhandler
    raise errorclass(errorvalue)
ProgrammingError: execute() first
 

2016-10-21 13:27:59,633 - knowledge_logger - main.py-handle-api- : sp_usercategory_list- None- (1054, "Unknown column 'user_category' in 'field list'") 

2016-10-21 13:27:59,634 - knowledge_logger - main.py : Traceback (most recent call last):
  File "/home/minds/projects/Aparajitha-SAAS/Src-server/server/main.py", line 162, in handle_api_request
    response_data = unbound_method(self, request_data, self._db)
  File "/home/minds/projects/Aparajitha-SAAS/Src-server/server/main.py", line 258, in handle_admin
    return controller.process_admin_request(request, db)
  File "/home/minds/projects/Aparajitha-SAAS/Src-server/server/controller/admincontroller.py", line 39, in process_admin_request
    result = get_user_groups(db, request_frame, session_user)
  File "/home/minds/projects/Aparajitha-SAAS/Src-server/server/controller/admincontroller.py", line 216, in get_user_groups
    form_categories = get_user_cetegories_db(db)
  File "/home/minds/projects/Aparajitha-SAAS/Src-server/server/controller/admincontroller.py", line 203, in get_user_cetegories_db
    rows = get_form_categories(db)
  File "/home/minds/projects/Aparajitha-SAAS/Src-server/server/database/admin.py", line 360, in get_form_categories
    return db.call_proc("sp_usercategory_list", None)
  File "/home/minds/projects/Aparajitha-SAAS/Src-server/server/dbase.py", line 688, in call_proc
    raise process_procedure_error(procedure_name, args, e)
RuntimeError: sp_usercategory_list- None- (1054, "Unknown column 'user_category' in 'field list'")
 

2016-10-21 13:28:52,956 - knowledge_logger - main.py-handle-api- : sp_industry_master_getindustries- ()- (1146, "Table 'compfie_knowledge_new.tbl_industries' doesn't exist") 

2016-10-21 13:28:52,957 - knowledge_logger - main.py : Traceback (most recent call last):
  File "/home/minds/projects/Aparajitha-SAAS/Src-server/server/main.py", line 162, in handle_api_request
    response_data = unbound_method(self, request_data, self._db)
  File "/home/minds/projects/Aparajitha-SAAS/Src-server/server/main.py", line 278, in handle_knowledge_master
    return controller.process_knowledge_master_request(request, db)
  File "/home/minds/projects/Aparajitha-SAAS/Src-server/server/controller/knowledgemastercontroller.py", line 82, in process_knowledge_master_request
    result = process_get_industry(db)
  File "/home/minds/projects/Aparajitha-SAAS/Src-server/server/controller/knowledgemastercontroller.py", line 176, in process_get_industry
    results = get_industries(db)
  File "/home/minds/projects/Aparajitha-SAAS/Src-server/server/database/knowledgemaster.py", line 46, in get_industries
    result = db.call_proc("sp_industry_master_getindustries", (), columns)
  File "/home/minds/projects/Aparajitha-SAAS/Src-server/server/dbase.py", line 688, in call_proc
    raise process_procedure_error(procedure_name, args, e)
RuntimeError: sp_industry_master_getindustries- ()- (1146, "Table 'compfie_knowledge_new.tbl_industries' doesn't exist")
 

2016-10-21 13:29:11,240 - knowledge_logger - main.py-handle-api- : sp_usercategory_list- None- (1054, "Unknown column 'user_category' in 'field list'") 

2016-10-21 13:29:11,240 - knowledge_logger - main.py : Traceback (most recent call last):
  File "/home/minds/projects/Aparajitha-SAAS/Src-server/server/main.py", line 162, in handle_api_request
    response_data = unbound_method(self, request_data, self._db)
  File "/home/minds/projects/Aparajitha-SAAS/Src-server/server/main.py", line 258, in handle_admin
    return controller.process_admin_request(request, db)
  File "/home/minds/projects/Aparajitha-SAAS/Src-server/server/controller/admincontroller.py", line 39, in process_admin_request
    result = get_user_groups(db, request_frame, session_user)
  File "/home/minds/projects/Aparajitha-SAAS/Src-server/server/controller/admincontroller.py", line 216, in get_user_groups
    form_categories = get_user_cetegories_db(db)
  File "/home/minds/projects/Aparajitha-SAAS/Src-server/server/controller/admincontroller.py", line 203, in get_user_cetegories_db
    rows = get_form_categories(db)
  File "/home/minds/projects/Aparajitha-SAAS/Src-server/server/database/admin.py", line 360, in get_form_categories
    return db.call_proc("sp_usercategory_list", None)
  File "/home/minds/projects/Aparajitha-SAAS/Src-server/server/dbase.py", line 688, in call_proc
    raise process_procedure_error(procedure_name, args, e)
RuntimeError: sp_usercategory_list- None- (1054, "Unknown column 'user_category' in 'field list'")
 

2016-10-21 13:31:13,499 - knowledge_logger - main.py-handle-api- : sp_industry_master_getindustries- ()- (1146, "Table 'compfie_knowledge_new.tbl_industries' doesn't exist") 

2016-10-21 13:31:13,499 - knowledge_logger - main.py : Traceback (most recent call last):
  File "/home/minds/projects/Aparajitha-SAAS/Src-server/server/main.py", line 162, in handle_api_request
    response_data = unbound_method(self, request_data, self._db)
  File "/home/minds/projects/Aparajitha-SAAS/Src-server/server/main.py", line 278, in handle_knowledge_master
    return controller.process_knowledge_master_request(request, db)
  File "/home/minds/projects/Aparajitha-SAAS/Src-server/server/controller/knowledgemastercontroller.py", line 82, in process_knowledge_master_request
    result = process_get_industry(db)
  File "/home/minds/projects/Aparajitha-SAAS/Src-server/server/controller/knowledgemastercontroller.py", line 176, in process_get_industry
    results = get_industries(db)
  File "/home/minds/projects/Aparajitha-SAAS/Src-server/server/database/knowledgemaster.py", line 46, in get_industries
    result = db.call_proc("sp_industry_master_getindustries", (), columns)
  File "/home/minds/projects/Aparajitha-SAAS/Src-server/server/dbase.py", line 688, in call_proc
    raise process_procedure_error(procedure_name, args, e)
RuntimeError: sp_industry_master_getindustries- ()- (1146, "Table 'compfie_knowledge_new.tbl_industries' doesn't exist")
 

