2016-12-17 11:21:50,392 - knowledge_logger - main.py-handle-api- : sp_tbl_units_check_unitgroupid- ['client_id', 1]- 1305 (42000): PROCEDURE compfie_knowledge_new.sp_tbl_units_check_unitgroupid does not exist 

2016-12-17 11:21:50,392 - knowledge_logger - main.py : Traceback (most recent call last):
  File "D:\Bogi\Project\Compfie\Src-server\server\main.py", line 203, in handle_api_request
    response_data = unbound_method(self, request_data, _db)
  File "D:\Bogi\Project\Compfie\Src-server\server\main.py", line 315, in handle_techno
    return controller.process_techno_request(request, db)
  File "D:\Bogi\Project\Compfie\Src-server\server\controller\technocontroller.py", line 81, in process_techno_request
    result = save_client(db, request_frame, session_user)
  File "D:\Bogi\Project\Compfie\Src-server\server\controller\technomastercontroller.py", line 288, in save_client
    is_valid = validate_duplicate_data(db, request, session_user)
  File "D:\Bogi\Project\Compfie\Src-server\server\controller\technomastercontroller.py", line 184, in validate_duplicate_data
    if not is_invalid_id(db, "client_id", client_id):
  File "D:\Bogi\Project\Compfie\Src-server\server\database\technomaster.py", line 1157, in is_invalid_id
    rows = db.call_proc("sp_tbl_units_check_unitgroupid", params)
  File "D:\Bogi\Project\Compfie\Src-server\server\dbase.py", line 782, in call_proc
    raise process_procedure_error(procedure_name, args, e)
RuntimeError: sp_tbl_units_check_unitgroupid- ['client_id', 1]- 1305 (42000): PROCEDURE compfie_knowledge_new.sp_tbl_units_check_unitgroupid does not exist
 

2016-12-17 11:22:53,983 - knowledge_logger - main.py-handle-api- : sp_tbl_units_check_unitgroupid- ['client_id', 1]- 1305 (42000): PROCEDURE compfie_knowledge_new.sp_tbl_units_check_unitgroupid does not exist 

2016-12-17 11:22:53,983 - knowledge_logger - main.py : Traceback (most recent call last):
  File "D:\Bogi\Project\Compfie\Src-server\server\main.py", line 203, in handle_api_request
    response_data = unbound_method(self, request_data, _db)
  File "D:\Bogi\Project\Compfie\Src-server\server\main.py", line 315, in handle_techno
    return controller.process_techno_request(request, db)
  File "D:\Bogi\Project\Compfie\Src-server\server\controller\technocontroller.py", line 81, in process_techno_request
    result = save_client(db, request_frame, session_user)
  File "D:\Bogi\Project\Compfie\Src-server\server\controller\technomastercontroller.py", line 288, in save_client
    is_valid = validate_duplicate_data(db, request, session_user)
  File "D:\Bogi\Project\Compfie\Src-server\server\controller\technomastercontroller.py", line 184, in validate_duplicate_data
    if not is_invalid_id(db, "client_id", client_id):
  File "D:\Bogi\Project\Compfie\Src-server\server\database\technomaster.py", line 1157, in is_invalid_id
    rows = db.call_proc("sp_tbl_units_check_unitgroupid", params)
  File "D:\Bogi\Project\Compfie\Src-server\server\dbase.py", line 782, in call_proc
    raise process_procedure_error(procedure_name, args, e)
RuntimeError: sp_tbl_units_check_unitgroupid- ['client_id', 1]- 1305 (42000): PROCEDURE compfie_knowledge_new.sp_tbl_units_check_unitgroupid does not exist
 

2016-12-17 11:27:04,980 - knowledge_logger - main.py-handle-api- : sp_tbl_units_checkduplication- [None, u'RG00001', None, 1]- 1305 (42000): PROCEDURE compfie_knowledge_new.sp_tbl_units_checkduplication does not exist 

2016-12-17 11:27:04,980 - knowledge_logger - main.py : Traceback (most recent call last):
  File "D:\Bogi\Project\Compfie\Src-server\server\main.py", line 203, in handle_api_request
    response_data = unbound_method(self, request_data, _db)
  File "D:\Bogi\Project\Compfie\Src-server\server\main.py", line 315, in handle_techno
    return controller.process_techno_request(request, db)
  File "D:\Bogi\Project\Compfie\Src-server\server\controller\technocontroller.py", line 81, in process_techno_request
    result = save_client(db, request_frame, session_user)
  File "D:\Bogi\Project\Compfie\Src-server\server\controller\technomastercontroller.py", line 333, in save_client
    is_valid_unit = validate_unit_data(db, request, div_ids, category_ids, client_id, session_user)
  File "D:\Bogi\Project\Compfie\Src-server\server\controller\technomastercontroller.py", line 246, in validate_unit_data
    if is_duplicate_unit_code(db, unit_id, unit.unit_code, client_id):
  File "D:\Bogi\Project\Compfie\Src-server\server\database\technomaster.py", line 1126, in is_duplicate_unit_code
    rows = db.call_proc("sp_tbl_units_checkduplication", params)
  File "D:\Bogi\Project\Compfie\Src-server\server\dbase.py", line 782, in call_proc
    raise process_procedure_error(procedure_name, args, e)
RuntimeError: sp_tbl_units_checkduplication- [None, u'RG00001', None, 1]- 1305 (42000): PROCEDURE compfie_knowledge_new.sp_tbl_units_checkduplication does not exist
 

2016-12-17 11:27:10,280 - knowledge_logger - main.py-handle-api- : sp_tbl_units_checkduplication- [None, u'RG00001', None, 1]- 1305 (42000): PROCEDURE compfie_knowledge_new.sp_tbl_units_checkduplication does not exist 

2016-12-17 11:27:10,280 - knowledge_logger - main.py : Traceback (most recent call last):
  File "D:\Bogi\Project\Compfie\Src-server\server\main.py", line 203, in handle_api_request
    response_data = unbound_method(self, request_data, _db)
  File "D:\Bogi\Project\Compfie\Src-server\server\main.py", line 315, in handle_techno
    return controller.process_techno_request(request, db)
  File "D:\Bogi\Project\Compfie\Src-server\server\controller\technocontroller.py", line 81, in process_techno_request
    result = save_client(db, request_frame, session_user)
  File "D:\Bogi\Project\Compfie\Src-server\server\controller\technomastercontroller.py", line 333, in save_client
    is_valid_unit = validate_unit_data(db, request, div_ids, category_ids, client_id, session_user)
  File "D:\Bogi\Project\Compfie\Src-server\server\controller\technomastercontroller.py", line 246, in validate_unit_data
    if is_duplicate_unit_code(db, unit_id, unit.unit_code, client_id):
  File "D:\Bogi\Project\Compfie\Src-server\server\database\technomaster.py", line 1126, in is_duplicate_unit_code
    rows = db.call_proc("sp_tbl_units_checkduplication", params)
  File "D:\Bogi\Project\Compfie\Src-server\server\dbase.py", line 782, in call_proc
    raise process_procedure_error(procedure_name, args, e)
RuntimeError: sp_tbl_units_checkduplication- [None, u'RG00001', None, 1]- 1305 (42000): PROCEDURE compfie_knowledge_new.sp_tbl_units_checkduplication does not exist
 

2016-12-17 15:57:55,000 - knowledge_logger - main.py-parse-request : expected a list with integer values , but received: [14, None] 

2016-12-17 15:57:55,009 - knowledge_logger - main.py : Traceback (most recent call last):
  File "D:\Bogi\Project\Compfie\Src-server\server\main.py", line 155, in _parse_request
    data
  File "D:\Bogi\Project\Compfie\Src-server\protocol\technomasters.py", line 2104, in parse_structure
    request, "technomasters", "Request"
  File "D:\Bogi\Project\Compfie\Src-server\protocol\jsonvalidators.py", line 479, in parse_VariantType
    return klass.parse_structure(data)
  File "D:\Bogi\Project\Compfie\Src-server\protocol\technomasters.py", line 118, in parse_structure
    return _Request_class_map[name].parse_inner_structure(data)
  File "D:\Bogi\Project\Compfie\Src-server\protocol\technomasters.py", line 775, in parse_inner_structure
    "client_id", "legal_entity_ids", "user_ids"
  File "D:\Bogi\Project\Compfie\Src-server\protocol\jsonvalidators.py", line 189, in parse_dictionary
    x = parse_dictionary_values(x, field_names, True)
  File "D:\Bogi\Project\Compfie\Src-server\protocol\jsonvalidators.py", line 378, in parse_dictionary_values
    val = parse_values(field_name, param, val, "parse")
  File "D:\Bogi\Project\Compfie\Src-server\protocol\jsonvalidators.py", line 311, in parse_values
    val = parse_int_list(val, int_length=_length)
  File "D:\Bogi\Project\Compfie\Src-server\protocol\jsonvalidators.py", line 242, in parse_int_list
    raise expectation_error("a list with integer values ", x)
ValueError: expected a list with integer values , but received: [14, None]
 

2016-12-17 15:57:55,019 - knowledge_logger - main.py-handle-api- : expected a list with integer values , but received: [14, None] 

2016-12-17 15:57:55,019 - knowledge_logger - main.py : Traceback (most recent call last):
  File "D:\Bogi\Project\Compfie\Src-server\server\main.py", line 196, in handle_api_request
    raise ValueError(request_data)
ValueError: expected a list with integer values , but received: [14, None]
 

2016-12-17 15:58:04,099 - knowledge_logger - main.py-parse-request : expected a list with integer values , but received: [14, None] 

2016-12-17 15:58:04,099 - knowledge_logger - main.py : Traceback (most recent call last):
  File "D:\Bogi\Project\Compfie\Src-server\server\main.py", line 155, in _parse_request
    data
  File "D:\Bogi\Project\Compfie\Src-server\protocol\technomasters.py", line 2104, in parse_structure
    request, "technomasters", "Request"
  File "D:\Bogi\Project\Compfie\Src-server\protocol\jsonvalidators.py", line 479, in parse_VariantType
    return klass.parse_structure(data)
  File "D:\Bogi\Project\Compfie\Src-server\protocol\technomasters.py", line 118, in parse_structure
    return _Request_class_map[name].parse_inner_structure(data)
  File "D:\Bogi\Project\Compfie\Src-server\protocol\technomasters.py", line 775, in parse_inner_structure
    "client_id", "legal_entity_ids", "user_ids"
  File "D:\Bogi\Project\Compfie\Src-server\protocol\jsonvalidators.py", line 189, in parse_dictionary
    x = parse_dictionary_values(x, field_names, True)
  File "D:\Bogi\Project\Compfie\Src-server\protocol\jsonvalidators.py", line 378, in parse_dictionary_values
    val = parse_values(field_name, param, val, "parse")
  File "D:\Bogi\Project\Compfie\Src-server\protocol\jsonvalidators.py", line 311, in parse_values
    val = parse_int_list(val, int_length=_length)
  File "D:\Bogi\Project\Compfie\Src-server\protocol\jsonvalidators.py", line 242, in parse_int_list
    raise expectation_error("a list with integer values ", x)
ValueError: expected a list with integer values , but received: [14, None]
 

2016-12-17 15:58:04,099 - knowledge_logger - main.py-handle-api- : expected a list with integer values , but received: [14, None] 

2016-12-17 15:58:04,099 - knowledge_logger - main.py : Traceback (most recent call last):
  File "D:\Bogi\Project\Compfie\Src-server\server\main.py", line 196, in handle_api_request
    raise ValueError(request_data)
ValueError: expected a list with integer values , but received: [14, None]
 

2016-12-17 19:25:12,457 - knowledge_logger - main.py-handle-api- : list index out of range 

2016-12-17 19:25:12,487 - knowledge_logger - main.py : Traceback (most recent call last):
  File "D:\Bogi\Project\Compfie\Src-server\server\main.py", line 203, in handle_api_request
    response_data = unbound_method(self, request_data, _db)
  File "D:\Bogi\Project\Compfie\Src-server\server\main.py", line 307, in handle_admin
    return controller.process_admin_request(request, db)
  File "D:\Bogi\Project\Compfie\Src-server\server\controller\admincontroller.py", line 116, in process_admin_request
    db, request_frame, session_user)
  File "D:\Bogi\Project\Compfie\Src-server\server\controller\admincontroller.py", line 518, in get_reassign_user_account_form_data
    user_categories = get_categories_for_user(db, session_user)
  File "D:\Bogi\Project\Compfie\Src-server\server\database\admin.py", line 1218, in get_categories_for_user
    for r in result[1]:
IndexError: list index out of range
 

