2016-08-28 19:40:02,339 - knowledge_logger - main.py-handle-api- : global name 'save_login_failure' is not defined
2016-08-28 19:40:02,340 - knowledge_logger - main.py : Traceback (most recent call last):
  File "/home/thickpadi5/Projects/aparajitha-saas/Src-server/server/main.py", line 143, in handle_api_request
    response_data = unbound_method(self, request_data, self._db)
  File "/home/thickpadi5/Projects/aparajitha-saas/Src-server/server/main.py", line 234, in handle_login
    return controller.process_login_request(request, db, self._ip_addess)
  File "/home/thickpadi5/Projects/aparajitha-saas/Src-server/server/controller/logincontroller.py", line 26, in process_login_request
    result = process_login(db, request, session_user_ip)
  File "/home/thickpadi5/Projects/aparajitha-saas/Src-server/server/controller/logincontroller.py", line 74, in process_login
    save_login_failure(db, session_user_ip)
NameError: global name 'save_login_failure' is not defined

2016-08-28 19:42:00,932 - knowledge_logger - main.py-handle-api- : global name 'updateColumnsList' is not defined
2016-08-28 19:42:00,932 - knowledge_logger - main.py : Traceback (most recent call last):
  File "/home/thickpadi5/Projects/aparajitha-saas/Src-server/server/main.py", line 143, in handle_api_request
    response_data = unbound_method(self, request_data, self._db)
  File "/home/thickpadi5/Projects/aparajitha-saas/Src-server/server/main.py", line 234, in handle_login
    return controller.process_login_request(request, db, self._ip_addess)
  File "/home/thickpadi5/Projects/aparajitha-saas/Src-server/server/controller/logincontroller.py", line 26, in process_login_request
    result = process_login(db, request, session_user_ip)
  File "/home/thickpadi5/Projects/aparajitha-saas/Src-server/server/controller/logincontroller.py", line 74, in process_login
    save_login_failure(db, session_user_ip)
  File "/home/thickpadi5/Projects/aparajitha-saas/Src-server/server/database/login.py", line 212, in save_login_failure
    tblUserLoginHistory, columns, value_list, updateColumnsList
NameError: global name 'updateColumnsList' is not defined

2016-08-28 19:52:55,174 - knowledge_logger - main.py-handle-api- : Transaction failed while processing data.
2016-08-28 19:52:55,175 - knowledge_logger - main.py : Traceback (most recent call last):
  File "/home/thickpadi5/Projects/aparajitha-saas/Src-server/server/main.py", line 143, in handle_api_request
    response_data = unbound_method(self, request_data, self._db)
  File "/home/thickpadi5/Projects/aparajitha-saas/Src-server/server/main.py", line 234, in handle_login
    return controller.process_login_request(request, db, self._ip_addess)
  File "/home/thickpadi5/Projects/aparajitha-saas/Src-server/server/controller/logincontroller.py", line 26, in process_login_request
    result = process_login(db, request, session_user_ip)
  File "/home/thickpadi5/Projects/aparajitha-saas/Src-server/server/controller/logincontroller.py", line 74, in process_login
    save_login_failure(db, session_user_ip)
  File "/home/thickpadi5/Projects/aparajitha-saas/Src-server/server/database/login.py", line 217, in save_login_failure
    db.increment(tblUserLoginHistory, increament_column, increament_cond)
  File "/home/thickpadi5/Projects/aparajitha-saas/Src-server/server/dbase.py", line 545, in increment
    rows = self.get_data(table, column, condition)
  File "/home/thickpadi5/Projects/aparajitha-saas/Src-server/server/dbase.py", line 323, in get_data
    rows = self.select_all(query)
  File "/home/thickpadi5/Projects/aparajitha-saas/Src-server/server/dbase.py", line 240, in select_all
    raise fetch_error()
RuntimeError: Transaction failed while processing data.

2016-08-28 19:57:31,273 - knowledge_logger - main.py-handle-api- : Transaction failed while processing data.
2016-08-28 19:57:31,274 - knowledge_logger - main.py : Traceback (most recent call last):
  File "/home/thickpadi5/Projects/aparajitha-saas/Src-server/server/main.py", line 143, in handle_api_request
    response_data = unbound_method(self, request_data, self._db)
  File "/home/thickpadi5/Projects/aparajitha-saas/Src-server/server/main.py", line 234, in handle_login
    return controller.process_login_request(request, db, self._ip_addess)
  File "/home/thickpadi5/Projects/aparajitha-saas/Src-server/server/controller/logincontroller.py", line 26, in process_login_request
    result = process_login(db, request, session_user_ip)
  File "/home/thickpadi5/Projects/aparajitha-saas/Src-server/server/controller/logincontroller.py", line 74, in process_login
    save_login_failure(db, session_user_ip)
  File "/home/thickpadi5/Projects/aparajitha-saas/Src-server/server/database/login.py", line 217, in save_login_failure
    db.increment(tblUserLoginHistory, increament_column, increament_cond)
  File "/home/thickpadi5/Projects/aparajitha-saas/Src-server/server/dbase.py", line 544, in increment
    rows = self.get_data(table, column, condition)
  File "/home/thickpadi5/Projects/aparajitha-saas/Src-server/server/dbase.py", line 323, in get_data
    rows = self.select_all(query)
  File "/home/thickpadi5/Projects/aparajitha-saas/Src-server/server/dbase.py", line 240, in select_all
    raise fetch_error()
RuntimeError: Transaction failed while processing data.

2016-08-28 19:58:17,654 - knowledge_logger - main.py-handle-api- : unhashable type: 'list'
2016-08-28 19:58:17,654 - knowledge_logger - main.py : Traceback (most recent call last):
  File "/home/thickpadi5/Projects/aparajitha-saas/Src-server/server/main.py", line 143, in handle_api_request
    response_data = unbound_method(self, request_data, self._db)
  File "/home/thickpadi5/Projects/aparajitha-saas/Src-server/server/main.py", line 234, in handle_login
    return controller.process_login_request(request, db, self._ip_addess)
  File "/home/thickpadi5/Projects/aparajitha-saas/Src-server/server/controller/logincontroller.py", line 26, in process_login_request
    result = process_login(db, request, session_user_ip)
  File "/home/thickpadi5/Projects/aparajitha-saas/Src-server/server/controller/logincontroller.py", line 74, in process_login
    save_login_failure(db, session_user_ip)
  File "/home/thickpadi5/Projects/aparajitha-saas/Src-server/server/database/login.py", line 217, in save_login_failure
    db.increment(tblUserLoginHistory, increament_column, increament_cond)
  File "/home/thickpadi5/Projects/aparajitha-saas/Src-server/server/dbase.py", line 546, in increment
    currentValue = rows[0][column]
TypeError: unhashable type: 'list'

2016-08-28 19:59:11,522 - knowledge_logger - main.py-handle-api- : can only concatenate list (not "str") to list
2016-08-28 19:59:11,522 - knowledge_logger - main.py : Traceback (most recent call last):
  File "/home/thickpadi5/Projects/aparajitha-saas/Src-server/server/main.py", line 143, in handle_api_request
    response_data = unbound_method(self, request_data, self._db)
  File "/home/thickpadi5/Projects/aparajitha-saas/Src-server/server/main.py", line 234, in handle_login
    return controller.process_login_request(request, db, self._ip_addess)
  File "/home/thickpadi5/Projects/aparajitha-saas/Src-server/server/controller/logincontroller.py", line 26, in process_login_request
    result = process_login(db, request, session_user_ip)
  File "/home/thickpadi5/Projects/aparajitha-saas/Src-server/server/controller/logincontroller.py", line 74, in process_login
    save_login_failure(db, session_user_ip)
  File "/home/thickpadi5/Projects/aparajitha-saas/Src-server/server/database/login.py", line 217, in save_login_failure
    db.increment(tblUserLoginHistory, increament_column, increament_cond)
  File "/home/thickpadi5/Projects/aparajitha-saas/Src-server/server/dbase.py", line 554, in increment
    return self.update(table, columns, values, condition)
  File "/home/thickpadi5/Projects/aparajitha-saas/Src-server/server/dbase.py", line 463, in update
    query += column+" = %s "
TypeError: can only concatenate list (not "str") to list

2016-08-28 20:00:40,791 - knowledge_logger - main.py-handle-api- : can only concatenate list (not "str") to list
2016-08-28 20:00:40,791 - knowledge_logger - main.py : Traceback (most recent call last):
  File "/home/thickpadi5/Projects/aparajitha-saas/Src-server/server/main.py", line 143, in handle_api_request
    response_data = unbound_method(self, request_data, self._db)
  File "/home/thickpadi5/Projects/aparajitha-saas/Src-server/server/main.py", line 234, in handle_login
    return controller.process_login_request(request, db, self._ip_addess)
  File "/home/thickpadi5/Projects/aparajitha-saas/Src-server/server/controller/logincontroller.py", line 26, in process_login_request
    result = process_login(db, request, session_user_ip)
  File "/home/thickpadi5/Projects/aparajitha-saas/Src-server/server/controller/logincontroller.py", line 74, in process_login
    save_login_failure(db, session_user_ip)
  File "/home/thickpadi5/Projects/aparajitha-saas/Src-server/server/database/login.py", line 217, in save_login_failure
    db.increment(tblUserLoginHistory, increament_column, increament_cond)
  File "/home/thickpadi5/Projects/aparajitha-saas/Src-server/server/dbase.py", line 555, in increment
    return self.update(table, columns, values, condition)
  File "/home/thickpadi5/Projects/aparajitha-saas/Src-server/server/dbase.py", line 463, in update
    query += column+" = %s "
TypeError: can only concatenate list (not "str") to list

2016-08-28 20:07:31,559 - knowledge_logger - main.py-handle-api- : 'Database' object has no attribute 'delete_login_failure_history'
2016-08-28 20:07:31,560 - knowledge_logger - main.py : Traceback (most recent call last):
  File "/home/thickpadi5/Projects/aparajitha-saas/Src-server/server/main.py", line 143, in handle_api_request
    response_data = unbound_method(self, request_data, self._db)
  File "/home/thickpadi5/Projects/aparajitha-saas/Src-server/server/main.py", line 234, in handle_login
    return controller.process_login_request(request, db, self._ip_addess)
  File "/home/thickpadi5/Projects/aparajitha-saas/Src-server/server/controller/logincontroller.py", line 26, in process_login_request
    result = process_login(db, request, session_user_ip)
  File "/home/thickpadi5/Projects/aparajitha-saas/Src-server/server/controller/logincontroller.py", line 69, in process_login
    db.delete_login_failure_history(session_user_ip)
AttributeError: 'Database' object has no attribute 'delete_login_failure_history'

2016-08-28 20:08:45,481 - knowledge_logger - main.py-handle-api- : 'Database' object has no attribute 'delete_login_failure_history'
2016-08-28 20:08:45,481 - knowledge_logger - main.py : Traceback (most recent call last):
  File "/home/thickpadi5/Projects/aparajitha-saas/Src-server/server/main.py", line 143, in handle_api_request
    response_data = unbound_method(self, request_data, self._db)
  File "/home/thickpadi5/Projects/aparajitha-saas/Src-server/server/main.py", line 234, in handle_login
    return controller.process_login_request(request, db, self._ip_addess)
  File "/home/thickpadi5/Projects/aparajitha-saas/Src-server/server/controller/logincontroller.py", line 26, in process_login_request
    result = process_login(db, request, session_user_ip)
  File "/home/thickpadi5/Projects/aparajitha-saas/Src-server/server/controller/logincontroller.py", line 69, in process_login
    db.delete_login_failure_history(session_user_ip)
AttributeError: 'Database' object has no attribute 'delete_login_failure_history'

2016-08-28 20:09:29,972 - knowledge_logger - main.py-handle-api- : 'Database' object has no attribute 'delete_login_failure_history'
2016-08-28 20:09:29,973 - knowledge_logger - main.py : Traceback (most recent call last):
  File "/home/thickpadi5/Projects/aparajitha-saas/Src-server/server/main.py", line 143, in handle_api_request
    response_data = unbound_method(self, request_data, self._db)
  File "/home/thickpadi5/Projects/aparajitha-saas/Src-server/server/main.py", line 234, in handle_login
    return controller.process_login_request(request, db, self._ip_addess)
  File "/home/thickpadi5/Projects/aparajitha-saas/Src-server/server/controller/logincontroller.py", line 26, in process_login_request
    result = process_login(db, request, session_user_ip)
  File "/home/thickpadi5/Projects/aparajitha-saas/Src-server/server/controller/logincontroller.py", line 69, in process_login
    db.delete_login_failure_history(session_user_ip)
AttributeError: 'Database' object has no attribute 'delete_login_failure_history'

2016-08-28 20:27:37,798 - knowledge_logger - main.py-handle-api- : global name 'get_login_attempt' is not defined
2016-08-28 20:27:37,798 - knowledge_logger - main.py : Traceback (most recent call last):
  File "/home/thickpadi5/Projects/aparajitha-saas/Src-server/server/main.py", line 143, in handle_api_request
    response_data = unbound_method(self, request_data, self._db)
  File "/home/thickpadi5/Projects/aparajitha-saas/Src-server/server/main.py", line 234, in handle_login
    return controller.process_login_request(request, db, self._ip_addess)
  File "/home/thickpadi5/Projects/aparajitha-saas/Src-server/server/controller/logincontroller.py", line 28, in process_login_request
    result = process_login(db, request, session_user_ip)
  File "/home/thickpadi5/Projects/aparajitha-saas/Src-server/server/controller/logincontroller.py", line 80, in process_login
    no_of_attempts = get_login_attempt(db, session_user_ip)
NameError: global name 'get_login_attempt' is not defined

