2016-12-23 09:10:33,488 - knowledge_logger - main.py-handle-api- : Transaction failed while processing data. 

2016-12-23 09:10:33,489 - knowledge_logger - main.py : Traceback (most recent call last):
  File "/home/ushadevi/Usha/Python/workspace/Compliance-Mirror/Know-src-server/server/main.py", line 201, in handle_api_request
    response_data = unbound_method(self, request_data, _db)
  File "/home/ushadevi/Usha/Python/workspace/Compliance-Mirror/Know-src-server/server/main.py", line 237, in handle_server_list
    gen.get_servers(db)
  File "/home/ushadevi/Usha/Python/workspace/Compliance-Mirror/Know-src-server/server/database/general.py", line 133, in get_servers
    rows = db.select_all(query)
  File "/home/ushadevi/Usha/Python/workspace/Compliance-Mirror/Know-src-server/server/dbase.py", line 298, in select_all
    raise fetch_error()
RuntimeError: Transaction failed while processing data.
 

2016-12-23 09:11:53,573 - knowledge_logger - main.py-handle-api- : Transaction failed while processing data. 

2016-12-23 09:11:53,573 - knowledge_logger - main.py : Traceback (most recent call last):
  File "/home/ushadevi/Usha/Python/workspace/Compliance-Mirror/Know-src-server/server/main.py", line 201, in handle_api_request
    response_data = unbound_method(self, request_data, _db)
  File "/home/ushadevi/Usha/Python/workspace/Compliance-Mirror/Know-src-server/server/main.py", line 237, in handle_server_list
    gen.get_servers(db)
  File "/home/ushadevi/Usha/Python/workspace/Compliance-Mirror/Know-src-server/server/database/general.py", line 133, in get_servers
    rows = db.select_all(query)
  File "/home/ushadevi/Usha/Python/workspace/Compliance-Mirror/Know-src-server/server/dbase.py", line 298, in select_all
    raise fetch_error()
RuntimeError: Transaction failed while processing data.
 

2016-12-23 09:13:13,594 - knowledge_logger - main.py-handle-api- : Transaction failed while processing data. 

2016-12-23 09:13:13,595 - knowledge_logger - main.py : Traceback (most recent call last):
  File "/home/ushadevi/Usha/Python/workspace/Compliance-Mirror/Know-src-server/server/main.py", line 201, in handle_api_request
    response_data = unbound_method(self, request_data, _db)
  File "/home/ushadevi/Usha/Python/workspace/Compliance-Mirror/Know-src-server/server/main.py", line 237, in handle_server_list
    gen.get_servers(db)
  File "/home/ushadevi/Usha/Python/workspace/Compliance-Mirror/Know-src-server/server/database/general.py", line 133, in get_servers
    rows = db.select_all(query)
  File "/home/ushadevi/Usha/Python/workspace/Compliance-Mirror/Know-src-server/server/dbase.py", line 298, in select_all
    raise fetch_error()
RuntimeError: Transaction failed while processing data.
 

2016-12-23 09:14:33,624 - knowledge_logger - main.py-handle-api- : Transaction failed while processing data. 

2016-12-23 09:14:33,626 - knowledge_logger - main.py : Traceback (most recent call last):
  File "/home/ushadevi/Usha/Python/workspace/Compliance-Mirror/Know-src-server/server/main.py", line 201, in handle_api_request
    response_data = unbound_method(self, request_data, _db)
  File "/home/ushadevi/Usha/Python/workspace/Compliance-Mirror/Know-src-server/server/main.py", line 237, in handle_server_list
    gen.get_servers(db)
  File "/home/ushadevi/Usha/Python/workspace/Compliance-Mirror/Know-src-server/server/database/general.py", line 133, in get_servers
    rows = db.select_all(query)
  File "/home/ushadevi/Usha/Python/workspace/Compliance-Mirror/Know-src-server/server/dbase.py", line 298, in select_all
    raise fetch_error()
RuntimeError: Transaction failed while processing data.
 

2016-12-23 09:15:53,695 - knowledge_logger - main.py-handle-api- : Transaction failed while processing data. 

2016-12-23 09:15:53,696 - knowledge_logger - main.py : Traceback (most recent call last):
  File "/home/ushadevi/Usha/Python/workspace/Compliance-Mirror/Know-src-server/server/main.py", line 201, in handle_api_request
    response_data = unbound_method(self, request_data, _db)
  File "/home/ushadevi/Usha/Python/workspace/Compliance-Mirror/Know-src-server/server/main.py", line 237, in handle_server_list
    gen.get_servers(db)
  File "/home/ushadevi/Usha/Python/workspace/Compliance-Mirror/Know-src-server/server/database/general.py", line 133, in get_servers
    rows = db.select_all(query)
  File "/home/ushadevi/Usha/Python/workspace/Compliance-Mirror/Know-src-server/server/dbase.py", line 298, in select_all
    raise fetch_error()
RuntimeError: Transaction failed while processing data.
 

2016-12-23 09:17:13,764 - knowledge_logger - main.py-handle-api- : Transaction failed while processing data. 

2016-12-23 09:17:13,765 - knowledge_logger - main.py : Traceback (most recent call last):
  File "/home/ushadevi/Usha/Python/workspace/Compliance-Mirror/Know-src-server/server/main.py", line 201, in handle_api_request
    response_data = unbound_method(self, request_data, _db)
  File "/home/ushadevi/Usha/Python/workspace/Compliance-Mirror/Know-src-server/server/main.py", line 237, in handle_server_list
    gen.get_servers(db)
  File "/home/ushadevi/Usha/Python/workspace/Compliance-Mirror/Know-src-server/server/database/general.py", line 133, in get_servers
    rows = db.select_all(query)
  File "/home/ushadevi/Usha/Python/workspace/Compliance-Mirror/Know-src-server/server/dbase.py", line 298, in select_all
    raise fetch_error()
RuntimeError: Transaction failed while processing data.
 

2016-12-23 09:18:33,857 - knowledge_logger - main.py-handle-api- : Transaction failed while processing data. 

2016-12-23 09:18:33,858 - knowledge_logger - main.py : Traceback (most recent call last):
  File "/home/ushadevi/Usha/Python/workspace/Compliance-Mirror/Know-src-server/server/main.py", line 201, in handle_api_request
    response_data = unbound_method(self, request_data, _db)
  File "/home/ushadevi/Usha/Python/workspace/Compliance-Mirror/Know-src-server/server/main.py", line 237, in handle_server_list
    gen.get_servers(db)
  File "/home/ushadevi/Usha/Python/workspace/Compliance-Mirror/Know-src-server/server/database/general.py", line 133, in get_servers
    rows = db.select_all(query)
  File "/home/ushadevi/Usha/Python/workspace/Compliance-Mirror/Know-src-server/server/dbase.py", line 298, in select_all
    raise fetch_error()
RuntimeError: Transaction failed while processing data.
 

2016-12-23 09:19:53,936 - knowledge_logger - main.py-handle-api- : Transaction failed while processing data. 

2016-12-23 09:19:53,937 - knowledge_logger - main.py : Traceback (most recent call last):
  File "/home/ushadevi/Usha/Python/workspace/Compliance-Mirror/Know-src-server/server/main.py", line 201, in handle_api_request
    response_data = unbound_method(self, request_data, _db)
  File "/home/ushadevi/Usha/Python/workspace/Compliance-Mirror/Know-src-server/server/main.py", line 237, in handle_server_list
    gen.get_servers(db)
  File "/home/ushadevi/Usha/Python/workspace/Compliance-Mirror/Know-src-server/server/database/general.py", line 133, in get_servers
    rows = db.select_all(query)
  File "/home/ushadevi/Usha/Python/workspace/Compliance-Mirror/Know-src-server/server/dbase.py", line 298, in select_all
    raise fetch_error()
RuntimeError: Transaction failed while processing data.
 

2016-12-23 09:21:14,034 - knowledge_logger - main.py-handle-api- : Transaction failed while processing data. 

2016-12-23 09:21:14,035 - knowledge_logger - main.py : Traceback (most recent call last):
  File "/home/ushadevi/Usha/Python/workspace/Compliance-Mirror/Know-src-server/server/main.py", line 201, in handle_api_request
    response_data = unbound_method(self, request_data, _db)
  File "/home/ushadevi/Usha/Python/workspace/Compliance-Mirror/Know-src-server/server/main.py", line 237, in handle_server_list
    gen.get_servers(db)
  File "/home/ushadevi/Usha/Python/workspace/Compliance-Mirror/Know-src-server/server/database/general.py", line 133, in get_servers
    " inner join tbl_database_server as t2 on t1.database_server_id = t2.database_server_id " + \
  File "/home/ushadevi/Usha/Python/workspace/Compliance-Mirror/Know-src-server/server/dbase.py", line 298, in select_all
    raise fetch_error()
RuntimeError: Transaction failed while processing data.
 

2016-12-23 09:22:09,861 - knowledge_logger - main.py-handle-api- : 'database_name' 

2016-12-23 09:22:09,861 - knowledge_logger - main.py : Traceback (most recent call last):
  File "/home/ushadevi/Usha/Python/workspace/Compliance-Mirror/Know-src-server/server/main.py", line 201, in handle_api_request
    response_data = unbound_method(self, request_data, _db)
  File "/home/ushadevi/Usha/Python/workspace/Compliance-Mirror/Know-src-server/server/main.py", line 237, in handle_server_list
    gen.get_servers(db)
  File "/home/ushadevi/Usha/Python/workspace/Compliance-Mirror/Know-src-server/server/database/general.py", line 144, in get_servers
    return return_companies(rows)
  File "/home/ushadevi/Usha/Python/workspace/Compliance-Mirror/Know-src-server/server/database/general.py", line 163, in return_companies
    d["database_name"],
KeyError: 'database_name'
 

2016-12-23 12:00:08,827 - knowledge_logger - main.py-handle-api- : Failed getting connection; pool exhausted 

2016-12-23 12:00:08,828 - knowledge_logger - main.py : Traceback (most recent call last):
  File "/home/ushadevi/Usha/Python/workspace/Compliance-Mirror/Know-src-server/server/main.py", line 207, in handle_api_request
    _db_con = self._con_pool.get_connection()
  File "/home/ushadevi/.local/lib/python2.7/site-packages/mysql/connector/pooling.py", line 310, in get_connection
    "Failed getting connection; pool exhausted")
PoolError: Failed getting connection; pool exhausted
 

2016-12-23 12:00:12,393 - knowledge_logger - main.py-handle-api- : Failed getting connection; pool exhausted 

2016-12-23 12:00:12,394 - knowledge_logger - main.py : Traceback (most recent call last):
  File "/home/ushadevi/Usha/Python/workspace/Compliance-Mirror/Know-src-server/server/main.py", line 207, in handle_api_request
    _db_con = self._con_pool.get_connection()
  File "/home/ushadevi/.local/lib/python2.7/site-packages/mysql/connector/pooling.py", line 310, in get_connection
    "Failed getting connection; pool exhausted")
PoolError: Failed getting connection; pool exhausted
 

2016-12-23 12:02:40,329 - knowledge_logger - main.py-handle-api- : Failed getting connection; pool exhausted 

2016-12-23 12:02:40,329 - knowledge_logger - main.py : Traceback (most recent call last):
  File "/home/ushadevi/Usha/Python/workspace/Compliance-Mirror/Know-src-server/server/main.py", line 207, in handle_api_request
    _db_con = self._con_pool.get_connection()
  File "/home/ushadevi/.local/lib/python2.7/site-packages/mysql/connector/pooling.py", line 310, in get_connection
    "Failed getting connection; pool exhausted")
PoolError: Failed getting connection; pool exhausted
 

2016-12-23 12:03:55,939 - knowledge_logger - main.py-handle-api- : Failed getting connection; pool exhausted 

2016-12-23 12:03:55,940 - knowledge_logger - main.py : Traceback (most recent call last):
  File "/home/ushadevi/Usha/Python/workspace/Compliance-Mirror/Know-src-server/server/main.py", line 208, in handle_api_request
    _db_con = self._con_pool.get_connection()
  File "/home/ushadevi/.local/lib/python2.7/site-packages/mysql/connector/pooling.py", line 310, in get_connection
    "Failed getting connection; pool exhausted")
PoolError: Failed getting connection; pool exhausted
 

2016-12-23 12:42:31,521 - knowledge_logger - main.py-parse-request : 400: Bad Request 

2016-12-23 12:42:31,522 - knowledge_logger - main.py : Traceback (most recent call last):
  File "/home/ushadevi/Usha/Python/workspace/Compliance-Mirror/Know-src-server/server/main.py", line 155, in _parse_request
    data = request.get_json(force=True)
  File "/home/ushadevi/.local/lib/python2.7/site-packages/flask/wrappers.py", line 161, in get_json
    rv = self.on_json_loading_failed(e)
  File "/home/ushadevi/.local/lib/python2.7/site-packages/flask/wrappers.py", line 181, in on_json_loading_failed
    raise BadRequest()
BadRequest: 400: Bad Request
 

2016-12-23 12:42:31,522 - knowledge_logger - main.py-handle-api- : 400: Bad Request 

2016-12-23 12:42:31,522 - knowledge_logger - main.py : Traceback (most recent call last):
  File "/home/ushadevi/Usha/Python/workspace/Compliance-Mirror/Know-src-server/server/main.py", line 204, in handle_api_request
    raise ValueError(request_data)
ValueError: 400: Bad Request
 

